<?xml version="1.0" encoding="UTF-8"?>
<testng-results skipped="0" failed="1" ignored="2" total="3" passed="0">
  <reporter-output>
  </reporter-output>
  <suite name="Suite1" duration-ms="103" started-at="2018-02-10T08:03:50Z" finished-at="2018-02-10T08:03:50Z">
    <groups>
      <group name="web">
        <method signature="PrivatTests.second()[pri:0, instance:privatTests.PrivatTests@3cda1055]" name="second" class="privatTests.PrivatTests"/>
      </group> <!-- web -->
    </groups>
    <test name="test1" duration-ms="52" started-at="2018-02-10T08:03:50Z" finished-at="2018-02-10T08:03:50Z">
      <class name="privatTests.PrivatTests">
        <test-method status="FAIL" signature="second()[pri:0, instance:privatTests.PrivatTests@3cda1055]" name="second" duration-ms="11" started-at="2018-02-10T08:03:50Z" finished-at="2018-02-10T08:03:50Z">
          <exception class="java.lang.AssertionError">
            <message>
              <![CDATA[expected [1] but found [2]]]>
            </message>
            <full-stacktrace>
              <![CDATA[java.lang.AssertionError: expected [1] but found [2]
at org.testng.Assert.fail(Assert.java:96)
at org.testng.Assert.failNotEquals(Assert.java:776)
at org.testng.Assert.assertEqualsImpl(Assert.java:137)
at org.testng.Assert.assertEquals(Assert.java:118)
at org.testng.Assert.assertEquals(Assert.java:453)
at org.testng.Assert.assertEquals(Assert.java:463)
at privatTests.PrivatTests.second(PrivatTests.java:16)
at sun.reflect.NativeMethodAccessorImpl.invoke0(Native Method)
at sun.reflect.NativeMethodAccessorImpl.invoke(NativeMethodAccessorImpl.java:62)
at sun.reflect.DelegatingMethodAccessorImpl.invoke(DelegatingMethodAccessorImpl.java:43)
at java.lang.reflect.Method.invoke(Method.java:497)
at org.testng.internal.MethodInvocationHelper.invokeMethod(MethodInvocationHelper.java:124)
at org.testng.internal.Invoker.invokeMethod(Invoker.java:580)
at org.testng.internal.Invoker.invokeTestMethod(Invoker.java:716)
at org.testng.internal.Invoker.invokeTestMethods(Invoker.java:988)
at org.testng.internal.TestMethodWorker.invokeTestMethods(TestMethodWorker.java:125)
at org.testng.internal.TestMethodWorker.run(TestMethodWorker.java:109)
at org.testng.TestRunner.privateRun(TestRunner.java:648)
at org.testng.TestRunner.run(TestRunner.java:505)
at org.testng.SuiteRunner.runTest(SuiteRunner.java:455)
at org.testng.SuiteRunner.runSequentially(SuiteRunner.java:450)
at org.testng.SuiteRunner.privateRun(SuiteRunner.java:415)
at org.testng.SuiteRunner.run(SuiteRunner.java:364)
at org.testng.SuiteRunnerWorker.runSuite(SuiteRunnerWorker.java:52)
at org.testng.SuiteRunnerWorker.run(SuiteRunnerWorker.java:84)
at org.testng.TestNG.runSuitesSequentially(TestNG.java:1208)
at org.testng.TestNG.runSuitesLocally(TestNG.java:1137)
at org.testng.TestNG.runSuites(TestNG.java:1049)
at org.testng.TestNG.run(TestNG.java:1017)
at org.apache.maven.surefire.testng.TestNGExecutor.run(TestNGExecutor.java:283)
at org.apache.maven.surefire.testng.TestNGXmlTestSuite.execute(TestNGXmlTestSuite.java:75)
at org.apache.maven.surefire.testng.TestNGProvider.invoke(TestNGProvider.java:120)
at org.apache.maven.surefire.booter.ForkedBooter.invokeProviderInSameClassLoader(ForkedBooter.java:373)
at org.apache.maven.surefire.booter.ForkedBooter.runSuitesInProcess(ForkedBooter.java:334)
at org.apache.maven.surefire.booter.ForkedBooter.execute(ForkedBooter.java:119)
at org.apache.maven.surefire.booter.ForkedBooter.main(ForkedBooter.java:407)
]]>
            </full-stacktrace>
          </exception> <!-- java.lang.AssertionError -->
          <reporter-output>
          </reporter-output>
        </test-method> <!-- second -->
      </class> <!-- privatTests.PrivatTests -->
    </test> <!-- test1 -->
    <test name="test2" duration-ms="0" started-at="2018-02-10T08:03:50Z" finished-at="2018-02-10T08:03:50Z">
    </test> <!-- test2 -->
  </suite> <!-- Suite1 -->
</testng-results>
